Workbook

Sheet Legend
B2: Diese Datei enthält Angaben zu einer einheitlichen Kodierung der Plots und der Artenmischungen sowie
B3: allgemeine Informationen zu den einzelnen Plots, die als Templates für verschiedene statistische Auswertungen verwendet werden können.
A5: Plotcode: | B5: Aus Blocknummer und Plotnummer habe wurde eine Code zusammengesetzt, so dass die Plots durch eine Variable
B6: eindeutig identifiziert werden können.
A8: Mixcode: | B8: Der Code für die Artenmischungen setzt sich aus der Artenzahl ( z.B.S01) und einer laufenden Nummer für die Mischung zusammen.
B9: Die Nummerierung beginnt jeweils mit den im großen Experiment verwendeten Mischungen und wird dann für die zusätzlichen Mischungen
B10: auf den kleinen Plots fortgesetzt.
B11: Die "Sonderflächen" sind folgendermaßen codiert:
B12: S00M01 - bare ground
B13: S99M02 - Succession with mowing
B14: S99M03 - Free Succession
B15: S99M04 - C4
B16: S99M05 - Meteorology-Plot (Block 2 Plot B030)
A18: Koordinaten große Plots: | B18: Für jeden Plot sind die Koordinaten (in m) der vier Plotecken (NO,SO;SW,NW) in einem von Jussi Baade gewählten Koordinatensystem
A19: Koordinaten kleine Plots: | B19: angegeben. Norden ist deshalb nicht exakt Norden, sondern an der Ausrichtung der Fläche orientiert!
B20: Diese Informationen können für Analysen verwendet werden, die die räumliche Anordnung der plots explizit berücksichtigen.
A22: Presence/Absence | B22: Die ausgesäten Artenmischungen aller Plots sind in Form einer Presence/Absence-Matrix aller 60 Arten des Artenpools angegeben.
A23: große und kleine Plots | B23: Für die Sonderflächen( bare ground, Sukzession, C4) enthalten die entsprechenden Zeilen daher nur Nullen.
B24: Das gleiche gilt für Flächen, auf denen nur Arten ausgesät wurden, die nicht im 60-Artenpool enthalten sind (Lolium per., Vicia sep., Solanum nig.).
A27: Plotinformation große Plots | B27: Die Tabelle enthält die wichtigsten "unabhängigen" Variablen für die statistische Auswertung des Versuchs. Dies sind im Einzelnen:
B28: plotcode
B29: mixcode
B30: block
B31: plot
B32: sowndiv - Anzahl ausgesäter Arten
B33: funcgr - Anzahl funktioneller Gruppen in der Aussaat
B34: numgrass - Anzahl Gräser
B35: numsherb - Anzahl kleiner Kräuter
B36: numtherb - Anzahl großer Kräuter
B37: numleg - Anzahl Leguminosen
B38: grass - Indikatorvariable: 1 - Gras in der Mischung, 0 - kein Gras in der Mischung
B39: sherb - Indikatorvariable: 1 - Kleine Kräuter in der Mischung, 0 - keine kleinen Kräuter in der Mischung
... B41: leg - Indikatorvariable: 1 - Leguminosen in der Mischung, 0 - keine Leguminosen in der Mischung
A43: Plotinformation kleine Plots | B43: Zusätzlich zu den Informationen bei den großen Plots gibt es hier Informationen, für welche Teilexperimente die Plots Verwendung finden.
B44: Zu beachten ist, dass einige Plots für mehrere Experimente Verwendung finden, aber häufig nicht der gesamte Plot.
B45: Monoculture: Lolium, Vicia sepium und Solanum nigrum-Plots werden mit zu den Monokulturen gezählt, auch wenn die Arten nicht zum
B46: 60-Arten-Pool gehören. Die entsprechenden Plots sind mit einem zusätzlichen Kommentar versehen.
B47: Replication: alle Plots, die Wiederholungen von Artenmischungen der großen Plots darstellen, auch bare ground, succession
B48: Evenness: alle Plots, die für das Evenness-Experiment Verwendung finden.
B49: Dies sind alles auch Wiederholungen der großen Plots.
...

Sheet Koordinaten große Plots
A1: plotcode | B1: NO | D1: SO | F1: SW | H1: NW | J1: Mitte
B2: R | C2: H | D2: R | E2: H | F2: R | G2: H | H2: R | I2: H
A3: B1A01 | B3: 1360 | C3: 1077 | D3: 1360 | E3: 1057 | F3: 1340 | G3: 1057 | H3: 1340 | I3: 1077 | J3: 1350 | K3: 1064.5
A4: B1A02 | B4: 1360 | C4: 1099 | D4: 1360 | E4: 1079 | F4: 1340 | G4: 1079 | H4: 1340 | I4: 1099 | J4: 1350 | K4: 1091.5
A5: B1A03 | B5: 1360 | C5: 1121 | D5: 1360 | E5: 1101 | F5: 1340 | G5: 1101 | H5: 1340 | I5: 1121 | J5: 1350 | K5: 1108.5
A6: B1A04 | B6: 1360 | C6: 1143 | D6: 1360 | E6: 1123 | F6: 1340 | G6: 1123 | H6: 1340 | I6: 1143 | J6: 1350 | K6: 1135.5
A7: B1A05 | B7: 1360 | C7: 1168 | D7: 1360 | E7: 1148 | F7: 1340 | G7: 1148 | H7: 1340 | I7: 1168 | J7: 1350 | K7: 1155.5
A8: B1A06 | B8: 1360 | C8: 1190 | D8: 1360 | E8: 1170 | F8: 1340 | G8: 1170 | H8: 1340 | I8: 1190 | J8: 1350 | K8: 1182.5
A9: B1A07 | B9: 1360 | C9: 1212 | D9: 1360 | E9: 1192 | F9: 1340 | G9: 1192 | H9: 1340 | I9: 1212 | J9: 1350 | K9: 1199.5
A10: B1A08 | B10: 1360 | C10: 1234 | D10: 1360 | E10: 1214 | F10: 1340 | G10: 1214 | H10: 1340 | I10: 1234 | J10: 1350 | K10: 1226.5
A11: B1A09 | B11: 1360 | C11: 1256 | D11: 1360 | E11: 1236 | F11: 1340 | G11: 1236 | H11: 1340 | I11: 1256 | J11: 1350 | K11: 1243.5
A12: B1A10 | B12: 1360 | C12: 1278 | D12: 1360 | E12: 1258 | F12: 1340 | G12: 1258 | H12: 1340 | I12: 1278 | J12: 1350 | K12: 1270.5
A13: B1A11 | B13: 1360 | C13: 1300 | D13: 1360 | E13: 1280 | F13: 1340 | G13: 1280 | H13: 1340 | I13: 1300 | J13: 1350 | K13: 1287.5
A14: B1A12 | B14: 1335 | C14: 1077 | D14: 1335 | E14: 1057 | F14: 1315 | G14: 1057 | H14: 1315 | I14: 1077 | J14: 1325 | K14: 1064.5
... A46: B2A22 | B46: 1278 | C46: 1278 | D46: 1278 | E46: 1258 | F46: 1258 | G46: 1258 | H46: 1258 | I46: 1278 | J46: 1268 | K46: 1270.5
A47: B2A23 | B47: 1278 | C47: 1033 | D47: 1278 | E47: 1023 | F47: 1258 | G47: 1023 | H47: 1258 | I47: 1033
A48: B3A01 | B48: 1246 | C48: 1033 | D48: 1246 | E48: 1013 | F48: 1226 | G48: 1013 | H48: 1226 | I48: 1033 | J48: 1236 | K48: 1020.5
A49: B3A02 | B49: 1246 | C49: 1055 | D49: 1246 | E49: 1035 | F49: 1226 | G49: 1035 | H49: 1226 | I49: 1055 | J49: 1236 | K49: 1047.5
A50: B3A03 | B50: 1246 | C50: 1077 | D50: 1246 | E50: 1057 | F50: 1226 | G50: 1057 | H50: 1226 | I50: 1077 | J50: 1236 | K50: 1064.5
A51: B3A04 | B51: 1246 | C51: 1099 | D51: 1246 | E51: 1079 | F51: 1226 | G51: 1079 | H51: 1226 | I51: 1099 | J51: 1236 | K51: 1091.5
A52: B3A05 | B52: 1246 | C52: 1121 | D52: 1246 | E52: 1101 | F52: 1226 | G52: 1101 | H52: 1226 | I52: 1121 | J52: 1236 | K52: 1108.5
A53: B3A06 | B53: 1246 | C53: 1143 | D53: 1246 | E53: 1123 | F53: 1226 | G53: 1123 | H53: 1226 | I53: 1143 | J53: 1236 | K53: 1135.5
A54: B3A07 | B54: 1246 | C54: 1168 | D54: 1246 | E54: 1148 | F54: 1226 | G54: 1148 | H54: 1226 | I54: 1168 | J54: 1236 | K54: 1155.5
A55: B3A08 | B55: 1246 | C55: 1190 | D55: 1246 | E55: 1170 | F55: 1226 | G55: 1170 | H55: 1226 | I55: 1190 | J55: 1236 | K55: 1182.5
A56: B3A09 | B56: 1246 | C56: 1212 | D56: 1246 | E56: 1192 | F56: 1226 | G56: 1192 | H56: 1226 | I56: 1212 | J56: 1236 | K56: 1199.5
A57: B3A10 | B57: 1246 | C57: 1234 | D57: 1246 | E57: 1214 | F57: 1226 | G57: 1214 | H57: 1226 | I57: 1234 | J57: 1236 | K57: 1226.5
A58: B3A11 | B58: 1246 | C58: 1256 | D58: 1246 | E58: 1236 | F58: 1226 | G58: 1236 | H58: 1226 | I58: 1256 | J58: 1236 | K58: 1243.5
A59: B3A12 | B59: 1246 | C59: 1278 | D59: 1246 | E59: 1258 | F59: 1226 | G59: 1258 | H59: 1226 | I59: 1278 | J59: 1236 | K59: 1270.5
... A64: B3A17 | B64: 1221 | C64: 1121 | D64: 1221 | E64: 1101 | F64: 1201 | G64: 1101 | H64: 1201 | I64: 1121 | J64: 1211 | K64: 1108.5
A65: B3A18 | B65: 1221 | C65: 1143 | D65: 1221 | E65: 1123 | F65: 1211 | G65: 1123 | H65: 1211 | I65: 1143
A66: B3A19 | B66: 1221 | C66: 1168 | D66: 1221 | E66: 1148 | F66: 1201 | G66: 1148 | H66: 1201 | I66: 1168 | J66: 1211 | K66: 1155.5
A67: B3A20 | B67: 1221 | C67: 1190 | D67: 1221 | E67: 1170 | F67: 1201 | G67: 1170 | H67: 1201 | I67: 1190 | J67: 1211 | K67: 1182.5
A68: B3A21 | B68: 1221 | C68: 1212 | D68: 1221 | E68: 1192 | F68: 1201 | G68: 1192 | H68: 1201 | I68: 1212 | J68: 1211 | K68: 1199.5
A69: B3A22 | B69: 1221 | C69: 1234 | D69: 1221 | E69: 1214 | F69: 1201 | G69: 1214 | H69: 1201 | I69: 1234 | J69: 1211 | K69: 1226.5
A70: B3A23 | B70: 1221 | C70: 1256 | D70: 1221 | E70: 1236 | F70: 1201 | G70: 1236 | H70: 1201 | I70: 1256 | J70: 1211 | K70: 1243.5
A71: B3A24 | B71: 1221 | C71: 1278 | D71: 1221 | E71: 1258 | F71: 1201 | G71: 1258 | H71: 1201 | I71: 1278 | J71: 1211 | K71: 1270.5
A72: B4A01 | B72: 1169 | C72: 1033 | D72: 1169 | E72: 1013 | F72: 1149 | G72: 1013 | H72: 1149 | I72: 1033 | J72: 1159 | K72: 1020.5
A73: B4A02 | B73: 1169 | C73: 1055 | D73: 1169 | E73: 1035 | F73: 1149 | G73: 1035 | H73: 1149 | I73: 1055 | J73: 1159 | K73: 1047.5
A74: B4A03 | B74: 1169 | C74: 1077 | D74: 1169 | E74: 1057 | F74: 1149 | G74: 1057 | H74: 1149 | I74: 1077 | J74: 1159 | K74: 1064.5
A75: B4A04 | B75: 1169 | C75: 1099 | D75: 1169 | E75: 1079 | F75: 1149 | G75: 1079 | H75: 1149 | I75: 1099 | J75: 1159 | K75: 1091.5
...

Sheet Koordinaten kleine Plots
A1: plotcode | B1: NO | D1: SO | F1: SW | H1: NW
B2: R | C2: H | D2: R | E2: H | F2: R | G2: H | H2: R | I2: H
A3: B1B001 | B3: 1313 | C3: 1060.5 | D3: 1313 | E3: 1057 | F3: 1309.5 | G3: 1057 | H3: 1309.5 | I3: 1060.5
A4: B1B002 | B4: 1313 | C4: 1064.5 | D4: 1313 | E4: 1061 | F4: 1309.5 | G4: 1061 | H4: 1309.5 | I4: 1064.5
A5: B1B003 | B5: 1313 | C5: 1068.5 | D5: 1313 | E5: 1065 | F5: 1309.5 | G5: 1065 | H5: 1309.5 | I5: 1068.5
A6: B1B004 | B6: 1313 | C6: 1072.5 | D6: 1313 | E6: 1069 | F6: 1309.5 | G6: 1069 | H6: 1309.5 | I6: 1072.5
A7: B1B005 | B7: 1313 | C7: 1076.5 | D7: 1313 | E7: 1073 | F7: 1309.5 | G7: 1073 | H7: 1309.5 | I7: 1076.5
A8: B1B006 | B8: 1313 | C8: 1082.5 | D8: 1313 | E8: 1079 | F8: 1309.5 | G8: 1079 | H8: 1309.5 | I8: 1082.5
A9: B1B007 | B9: 1313 | C9: 1086.5 | D9: 1313 | E9: 1083 | F9: 1309.5 | G9: 1083 | H9: 1309.5 | I9: 1086.5
A10: B1B008 | B10: 1313 | C10: 1090.5 | D10: 1313 | E10: 1087 | F10: 1309.5 | G10: 1087 | H10: 1309.5 | I10: 1090.5
A11: B1B009 | B11: 1313 | C11: 1094.5 | D11: 1313 | E11: 1091 | F11: 1309.5 | G11: 1091 | H11: 1309.5 | I11: 1094.5
A12: B1B010 | B12: 1313 | C12: 1098.5 | D12: 1313 | E12: 1095 | F12: 1309.5 | G12: 1095 | H12: 1309.5 | I12: 1098.5
A13: B1B011 | B13: 1313 | C13: 1104.5 | D13: 1313 | E13: 1101 | F13: 1309.5 | G13: 1101 | H13: 1309.5 | I13: 1104.5
A14: B1B012 | B14: 1313 | C14: 1108.5 | D14: 1313 | E14: 1105 | F14: 1309.5 | G14: 1105 | H14: 1309.5 | I14: 1108.5
... A407: B4B100 | B407: 1013.5 | C407: 1098.5 | D407: 1013.5 | E407: 1095 | F407: 1010 | G407: 1095 | H407: 1010 | I407: 1098.5

Sheet PresenceAbsence große Plots
A1: plotcode | B1: mixcode | C1: comment | D1: Alo pra | E1: Ant odo | F1: Arr ela | G1: Ave pub | H1: Bro ere | I1: Bro hor | J1: Cyn cri | K1: Dac glo | L1: Fes pra | M1: Fes rub | N1: Hol lan | O1: Luz cam | P1: Phl pra | Q1: Poa pra | R1: Poa tri | S1: Tri fla | T1: Aju rep | U1: Bel per | V1: Gle hed | W1: Leo aut | X1: Leo his | Y1: Pla lan | Z1: Pla med | AA1: Pri ver | AB1: Pru vul | AC1: Ran rep | AD1: Tar off | AE1: Ver cha | AF1: Ach mil | AG1: Ant syl | AH1: Cam pat | AI1: Car pra | AJ1: Car car | AK1: Cen jac | AL1: Cir ole | AM1: Cre bie | AN1: Dau car | AO1: Gal mol | AP1: Ger pra | AQ1: Her sph | AR1: Kna arv | AS1: Leu vul | AT1: Pas sat | AU1: Pim maj | AV1: Ran acr | AW1: Rum ace | AX1: San off | AY1: Tra pra | AZ1: Lat pra | BA1: Lot cor | BB1: Med lup | BC1: Med var | BD1: Ono vic | BE1: Tri cam | BF1: Tri dub | BG1: Tri fra | BH1: Tri hyb | BI1: Tri pra | BJ1: Tri rep | BK1: Vic cra
A2: B1A01 | B2: S16M12 | D2: 0 | E2: 1 | F2: 0 | G2: 1 | H2: 0 | I2: 1 | J2: 0 | K2: 0 | L2: 0 | M2: 0 | N2: 0 | O2: 0 | P2: 0 | Q2: 1 | R2: 0 | S2: 0 | T2: 1 | U2: 0 | V2: 0 | W2: 0 | X2: 0 | Y2: 1 | Z2: 0 | AA2: 0 | AB2: 0 | AC2: 1 | AD2: 1 | AE2: 0 | AF2: 0 | AG2: 1 | AH2: 0 | AI2: 0 | AJ2: 1 | AK2: 0 | AL2: 0 | AM2: 0 | AN2: 0 | AO2: 0 | AP2: 1 | AQ2: 0 | AR2: 0 | AS2: 0 | AT2: 0 | AU2: 0 | AV2: 0 | AW2: 0 | AX2: 0 | AY2: 1 | AZ2: 1 | BA2: 1 | BB2: 0 | BC2: 0 | BD2: 0 | BE2: 1 | BF2: 0 | BG2: 0 | BH2: 0 | BI2: 0 | BJ2: 0 | BK2: 1
A3: B1A02 | B3: S08M07 | D3: 1 | E3: 0 | F3: 0 | G3: 0 | H3: 1 | I3: 0 | J3: 0 | K3: 0 | L3: 0 | M3: 1 | N3: 0 | O3: 0 | P3: 1 | Q3: 0 | R3: 0 | S3: 0 | T3: 0 | U3: 0 | V3: 0 | W3: 0 | X3: 0 | Y3: 0 | Z3: 0 | AA3: 0 | AB3: 0 | AC3: 0 | AD3: 0 | AE3: 0 | AF3: 0 | AG3: 0 | AH3: 0 | AI3: 1 | AJ3: 0 | AK3: 0 | AL3: 0 | AM3: 0 | AN3: 0 | AO3: 0 | AP3: 0 | AQ3: 1 | AR3: 0 | AS3: 0 | AT3: 0 | AU3: 0 | AV3: 1 | AW3: 0 | AX3: 1 | AY3: 0 | AZ3: 0 | BA3: 0 | BB3: 0 | BC3: 0 | BD3: 0 | BE3: 0 | BF3: 0 | BG3: 0 | BH3: 0 | BI3: 0 | BJ3: 0 | BK3: 0
A4: B1A03 | B4: S08M11 | D4: 0 | E4: 0 | F4: 0 | G4: 0 | H4: 0 | I4: 0 | J4: 1 | K4: 0 | L4: 0 | M4: 0 | N4: 0 | O4: 0 | P4: 1 | Q4: 0 | R4: 0 | S4: 1 | T4: 0 | U4: 0 | V4: 1 | W4: 0 | X4: 0 | Y4: 0 | Z4: 0 | AA4: 1 | AB4: 0 | AC4: 0 | AD4: 0 | AE4: 1 | AF4: 0 | AG4: 0 | AH4: 0 | AI4: 0 | AJ4: 0 | AK4: 0 | AL4: 0 | AM4: 0 | AN4: 0 | AO4: 0 | AP4: 0 | AQ4: 0 | AR4: 0 | AS4: 0 | AT4: 0 | AU4: 0 | AV4: 0 | AW4: 0 | AX4: 0 | AY4: 0 | AZ4: 0 | BA4: 1 | BB4: 1 | BC4: 0 | BD4: 0 | BE4: 0 | BF4: 0 | BG4: 0 | BH4: 0 | BI4: 0 | BJ4: 0 | BK4: 0
A5: B1A04 | B5: S04M16 | D5: 0 | E5: 0 | F5: 0 | G5: 0 | H5: 0 | I5: 0 | J5: 0 | K5: 0 | L5: 1 | M5: 0 | N5: 0 | O5: 0 | P5: 0 | Q5: 0 | R5: 0 | S5: 0 | T5: 0 | U5: 0 | V5: 0 | W5: 0 | X5: 0 | Y5: 1 | Z5: 0 | AA5: 0 | AB5: 0 | AC5: 0 | AD5: 0 | AE5: 0 | AF5: 0 | AG5: 0 | AH5: 1 | AI5: 0 | AJ5: 0 | AK5: 0 | AL5: 0 | AM5: 0 | AN5: 0 | AO5: 0 | AP5: 0 | AQ5: 0 | AR5: 0 | AS5: 0 | AT5: 0 | AU5: 0 | AV5: 0 | AW5: 0 | AX5: 0 | AY5: 0 | AZ5: 0 | BA5: 0 | BB5: 0 | BC5: 0 | BD5: 1 | BE5: 0 | BF5: 0 | BG5: 0 | BH5: 0 | BI5: 0 | BJ5: 0 | BK5: 0
A6: B1A05 | B6: S02M07 | D6: 0 | E6: 0 | F6: 0 | G6: 0 | H6: 0 | I6: 0 | J6: 0 | K6: 0 | L6: 0 | M6: 0 | N6: 0 | O6: 0 | P6: 0 | Q6: 0 | R6: 0 | S6: 0 | T6: 0 | U6: 0 | V6: 0 | W6: 0 | X6: 0 | Y6: 0 | Z6: 0 | AA6: 0 | AB6: 0 | AC6: 0 | AD6: 0 | AE6: 0 | AF6: 0 | AG6: 0 | AH6: 0 | AI6: 0 | AJ6: 0 | AK6: 0 | AL6: 0 | AM6: 0 | AN6: 0 | AO6: 0 | AP6: 0 | AQ6: 0 | AR6: 0 | AS6: 0 | AT6: 0 | AU6: 0 | AV6: 0 | AW6: 0 | AX6: 0 | AY6: 0 | AZ6: 0 | BA6: 0 | BB6: 1 | BC6: 0 | BD6: 1 | BE6: 0 | BF6: 0 | BG6: 0 | BH6: 0 | BI6: 0 | BJ6: 0 | BK6: 0
A7: B1A06 | B7: S16M03 | D7: 1 | E7: 1 | F7: 0 | G7: 1 | H7: 0 | I7: 1 | J7: 0 | K7: 0 | L7: 0 | M7: 0 | N7: 1 | O7: 0 | P7: 0 | Q7: 1 | R7: 1 | S7: 1 | T7: 0 | U7: 0 | V7: 0 | W7: 0 | X7: 0 | Y7: 0 | Z7: 0 | AA7: 0 | AB7: 0 | AC7: 0 | AD7: 0 | AE7: 0 | AF7: 1 | AG7: 1 | AH7: 1 | AI7: 0 | AJ7: 0 | AK7: 1 | AL7: 0 | AM7: 0 | AN7: 0 | AO7: 0 | AP7: 1 | AQ7: 1 | AR7: 0 | AS7: 1 | AT7: 0 | AU7: 1 | AV7: 0 | AW7: 0 | AX7: 0 | AY7: 0 | AZ7: 0 | BA7: 0 | BB7: 0 | BC7: 0 | BD7: 0 | BE7: 0 | BF7: 0 | BG7: 0 | BH7: 0 | BI7: 0 | BJ7: 0 | BK7: 0
A8: B1A07 | B8: S02M06 | D8: 0 | E8: 0 | F8: 0 | G8: 0 | H8: 0 | I8: 0 | J8: 0 | K8: 0 | L8: 0 | M8: 0 | N8: 0 | O8: 0 | P8: 0 | Q8: 0 | R8: 0 | S8: 0 | T8: 0 | U8: 0 | V8: 0 | W8: 0 | X8: 0 | Y8: 0 | Z8: 0 | AA8: 0 | AB8: 0 | AC8: 0 | AD8: 0 | AE8: 0 | AF8: 0 | AG8: 0 | AH8: 0 | AI8: 0 | AJ8: 0 | AK8: 0 | AL8: 0 | AM8: 0 | AN8: 0 | AO8: 0 | AP8: 0 | AQ8: 0 | AR8: 0 | AS8: 0 | AT8: 0 | AU8: 0 | AV8: 1 | AW8: 0 | AX8: 1 | AY8: 0 | AZ8: 0 | BA8: 0 | BB8: 0 | BC8: 0 | BD8: 0 | BE8: 0 | BF8: 0 | BG8: 0 | BH8: 0 | BI8: 0 | BJ8: 0 | BK8: 0
A9: B1A08 | B9: S01M16 | D9: 0 | E9: 0 | F9: 0 | G9: 0 | H9: 0 | I9: 0 | J9: 0 | K9: 0 | L9: 0 | M9: 0 | N9: 0 | O9: 0 | P9: 0 | Q9: 0 | R9: 0 | S9: 0 | T9: 0 | U9: 0 | V9: 0 | W9: 0 | X9: 0 | Y9: 0 | Z9: 0 | AA9: 0 | AB9: 0 | AC9: 0 | AD9: 0 | AE9: 0 | AF9: 0 | AG9: 0 | AH9: 0 | AI9: 0 | AJ9: 0 | AK9: 0 | AL9: 0 | AM9: 0 | AN9: 0 | AO9: 0 | AP9: 0 | AQ9: 0 | AR9: 0 | AS9: 0 | AT9: 0 | AU9: 0 | AV9: 0 | AW9: 0 | AX9: 0 | AY9: 0 | AZ9: 0 | BA9: 0 | BB9: 0 | BC9: 1 | BD9: 0 | BE9: 0 | BF9: 0 | BG9: 0 | BH9: 0 | BI9: 0 | BJ9: 0 | BK9: 0
A10: B1A09 | B10: S01M01 | D10: 0 | E10: 0 | F10: 0 | G10: 0 | H10: 0 | I10: 0 | J10: 1 | K10: 0 | L10: 0 | M10: 0 | N10: 0 | O10: 0 | P10: 0 | Q10: 0 | R10: 0 | S10: 0 | T10: 0 | U10: 0 | V10: 0 | W10: 0 | X10: 0 | Y10: 0 | Z10: 0 | AA10: 0 | AB10: 0 | AC10: 0 | AD10: 0 | AE10: 0 | AF10: 0 | AG10: 0 | AH10: 0 | AI10: 0 | AJ10: 0 | AK10: 0 | AL10: 0 | AM10: 0 | AN10: 0 | AO10: 0 | AP10: 0 | AQ10: 0 | AR10: 0 | AS10: 0 | AT10: 0 | AU10: 0 | AV10: 0 | AW10: 0 | AX10: 0 | AY10: 0 | AZ10: 0 | BA10: 0 | BB10: 0 | BC10: 0 | BD10: 0 | BE10: 0 | BF10: 0 | BG10: 0 | BH10: 0 | BI10: 0 | BJ10: 0 | BK10: 0
A11: B1A10 | B11: S00M01 | C11: bare | D11: 0 | E11: 0 | F11: 0 | G11: 0 | H11: 0 | I11: 0 | J11: 0 | K11: 0 | L11: 0 | M11: 0 | N11: 0 | O11: 0 | P11: 0 | Q11: 0 | R11: 0 | S11: 0 | T11: 0 | U11: 0 | V11: 0 | W11: 0 | X11: 0 | Y11: 0 | Z11: 0 | AA11: 0 | AB11: 0 | AC11: 0 | AD11: 0 | AE11: 0 | AF11: 0 | AG11: 0 | AH11: 0 | AI11: 0 | AJ11: 0 | AK11: 0 | AL11: 0 | AM11: 0 | AN11: 0 | AO11: 0 | AP11: 0 | AQ11: 0 | AR11: 0 | AS11: 0 | AT11: 0 | AU11: 0 | AV11: 0 | AW11: 0 | AX11: 0 | AY11: 0 | AZ11: 0 | BA11: 0 | BB11: 0 | BC11: 0 | BD11: 0 | BE11: 0 | BF11: 0 | BG11: 0 | BH11: 0 | BI11: 0 | BJ11: 0 | BK11: 0
A12: B1A11 | B12: S16M14 | D12: 0 | E12: 0 | F12: 0 | G12: 0 | H12: 0 | I12: 0 | J12: 0 | K12: 0 | L12: 0 | M12: 0 | N12: 0 | O12: 0 | P12: 0 | Q12: 0 | R12: 0 | S12: 0 | T12: 0 | U12: 0 | V12: 0 | W12: 0 | X12: 0 | Y12: 0 | Z12: 0 | AA12: 0 | AB12: 0 | AC12: 0 | AD12: 0 | AE12: 0 | AF12: 1 | AG12: 1 | AH12: 1 | AI12: 1 | AJ12: 0 | AK12: 0 | AL12: 1 | AM12: 1 | AN12: 1 | AO12: 1 | AP12: 1 | AQ12: 1 | AR12: 0 | AS12: 1 | AT12: 1 | AU12: 0 | AV12: 1 | AW12: 1 | AX12: 1 | AY12: 1 | AZ12: 0 | BA12: 0 | BB12: 0 | BC12: 0 | BD12: 0 | BE12: 0 | BF12: 0 | BG12: 0 | BH12: 0 | BI12: 0 | BJ12: 0 | BK12: 0
A13: B1A12 | B13: S08M04 | D13: 0 | E13: 0 | F13: 0 | G13: 0 | H13: 0 | I13: 0 | J13: 0 | K13: 0 | L13: 0 | M13: 0 | N13: 0 | O13: 0 | P13: 0 | Q13: 0 | R13: 0 | S13: 0 | T13: 0 | U13: 0 | V13: 0 | W13: 0 | X13: 0 | Y13: 0 | Z13: 0 | AA13: 0 | AB13: 0 | AC13: 0 | AD13: 0 | AE13: 0 | AF13: 0 | AG13: 0 | AH13: 0 | AI13: 0 | AJ13: 0 | AK13: 0 | AL13: 0 | AM13: 0 | AN13: 0 | AO13: 0 | AP13: 0 | AQ13: 0 | AR13: 0 | AS13: 0 | AT13: 0 | AU13: 0 | AV13: 0 | AW13: 0 | AX13: 0 | AY13: 0 | AZ13: 1 | BA13: 0 | BB13: 1 | BC13: 1 | BD13: 1 | BE13: 1 | BF13: 1 | BG13: 0 | BH13: 1 | BI13: 1 | BJ13: 0 | BK13: 0
A14: B1A13 | B14: S04M04 | D14: 0 | E14: 0 | F14: 0 | G14: 0 | H14: 0 | I14: 0 | J14: 0 | K14: 0 | L14: 0 | M14: 0 | N14: 0 | O14: 0 | P14: 0 | Q14: 0 | R14: 0 | S14: 0 | T14: 0 | U14: 0 | V14: 0 | W14: 0 | X14: 0 | Y14: 0 | Z14: 0 | AA14: 0 | AB14: 0 | AC14: 0 | AD14: 0 | AE14: 0 | AF14: 0 | AG14: 0 | AH14: 0 | AI14: 0 | AJ14: 0 | AK14: 0 | AL14: 0 | AM14: 0 | AN14: 0 | AO14: 0 | AP14: 0 | AQ14: 0 | AR14: 0 | AS14: 0 | AT14: 0 | AU14: 0 | AV14: 0 | AW14: 0 | AX14: 0 | AY14: 0 | AZ14: 0 | BA14: 1 | BB14: 1 | BC14: 1 | BD14: 1 | BE14: 0 | BF14: 0 | BG14: 0 | BH14: 0 | BI14: 0 | BJ14: 0 | BK14: 0
A15: B1A14 | B15: S08M15 | D15: 0 | E15: 0 | F15: 0 | G15: 0 | H15: 0 | I15: 0 | J15: 0 | K15: 0 | L15: 0 | M15: 0 | N15: 0 | O15: 1 | P15: 0 | Q15: 0 | R15: 0 | S15: 1 | T15: 0 | U15: 0 | V15: 0 | W15: 0 | X15: 1 | Y15: 1 | Z15: 0 | AA15: 0 | AB15: 0 | AC15: 0 | AD15: 0 | AE15: 0 | AF15: 0 | AG15: 1 | AH15: 0 | AI15: 0 | AJ15: 0 | AK15: 0 | AL15: 0 | AM15: 0 | AN15: 1 | AO15: 0 | AP15: 0 | AQ15: 0 | AR15: 0 | AS15: 0 | AT15: 0 | AU15: 0 | AV15: 0 | AW15: 0 | AX15: 0 | AY15: 0 | AZ15: 0 | BA15: 0 | BB15: 0 | BC15: 0 | BD15: 0 | BE15: 1 | BF15: 0 | BG15: 1 | BH15: 0 | BI15: 0 | BJ15: 0 | BK15: 0
A16: B1A15 | B16: S01M11 | D16: 0 | E16: 0 | F16: 0 | G16: 0 | H16: 0 | I16: 0 | J16: 0 | K16: 0 | L16: 0 | M16: 0 | N16: 0 | O16: 0 | P16: 0 | Q16: 0 | R16: 0 | S16: 0 | T16: 0 | U16: 0 | V16: 0 | W16: 0 | X16: 0 | Y16: 0 | Z16: 0 | AA16: 0 | AB16: 0 | AC16: 0 | AD16: 0 | AE16: 0 | AF16: 0 | AG16: 0 | AH16: 0 | AI16: 0 | AJ16: 0 | AK16: 0 | AL16: 0 | AM16: 1 | AN16: 0 | AO16: 0 | AP16: 0 | AQ16: 0 | AR16: 0 | AS16: 0 | AT16: 0 | AU16: 0 | AV16: 0 | AW16: 0 | AX16: 0 | AY16: 0 | AZ16: 0 | BA16: 0 | BB16: 0 | BC16: 0 | BD16: 0 | BE16: 0 | BF16: 0 | BG16: 0 | BH16: 0 | BI16: 0 | BJ16: 0 | BK16: 0
A17: B1A16 | B17: S02M10 | D17: 0 | E17: 0 | F17: 0 | G17: 0 | H17: 0 | I17: 0 | J17: 0 | K17: 0 | L17: 0 | M17: 0 | N17: 0 | O17: 0 | P17: 0 | Q17: 1 | R17: 0 | S17: 0 | T17: 0 | U17: 0 | V17: 0 | W17: 0 | X17: 0 | Y17: 1 | Z17: 0 | AA17: 0 | AB17: 0 | AC17: 0 | AD17: 0 | AE17: 0 | AF17: 0 | AG17: 0 | AH17: 0 | AI17: 0 | AJ17: 0 | AK17: 0 | AL17: 0 | AM17: 0 | AN17: 0 | AO17: 0 | AP17: 0 | AQ17: 0 | AR17: 0 | AS17: 0 | AT17: 0 | AU17: 0 | AV17: 0 | AW17: 0 | AX17: 0 | AY17: 0 | AZ17: 0 | BA17: 0 | BB17: 0 | BC17: 0 | BD17: 0 | BE17: 0 | BF17: 0 | BG17: 0 | BH17: 0 | BI17: 0 | BJ17: 0 | BK17: 0
A18: B1A17 | B18: S02M14 | D18: 1 | E18: 0 | F18: 0 | G18: 0 | H18: 0 | I18: 0 | J18: 0 | K18: 0 | L18: 0 | M18: 0 | N18: 0 | O18: 0 | P18: 0 | Q18: 0 | R18: 0 | S18: 0 | T18: 0 | U18: 0 | V18: 0 | W18: 0 | X18: 0 | Y18: 0 | Z18: 0 | AA18: 0 | AB18: 0 | AC18: 0 | AD18: 0 | AE18: 0 | AF18: 0 | AG18: 0 | AH18: 0 | AI18: 0 | AJ18: 0 | AK18: 0 | AL18: 0 | AM18: 0 | AN18: 1 | AO18: 0 | AP18: 0 | AQ18: 0 | AR18: 0 | AS18: 0 | AT18: 0 | AU18: 0 | AV18: 0 | AW18: 0 | AX18: 0 | AY18: 0 | AZ18: 0 | BA18: 0 | BB18: 0 | BC18: 0 | BD18: 0 | BE18: 0 | BF18: 0 | BG18: 0 | BH18: 0 | BI18: 0 | BJ18: 0 | BK18: 0
A19: B1A18 | B19: S01M07 | D19: 0 | E19: 0 | F19: 0 | G19: 0 | H19: 0 | I19: 0 | J19: 0 | K19: 0 | L19: 0 | M19: 0 | N19: 0 | O19: 0 | P19: 0 | Q19: 0 | R19: 0 | S19: 0 | T19: 0 | U19: 0 | V19: 0 | W19: 0 | X19: 0 | Y19: 0 | Z19: 0 | AA19: 0 | AB19: 1 | AC19: 0 | AD19: 0 | AE19: 0 | AF19: 0 | AG19: 0 | AH19: 0 | AI19: 0 | AJ19: 0 | AK19: 0 | AL19: 0 | AM19: 0 | AN19: 0 | AO19: 0 | AP19: 0 | AQ19: 0 | AR19: 0 | AS19: 0 | AT19: 0 | AU19: 0 | AV19: 0 | AW19: 0 | AX19: 0 | AY19: 0 | AZ19: 0 | BA19: 0 | BB19: 0 | BC19: 0 | BD19: 0 | BE19: 0 | BF19: 0 | BG19: 0 | BH19: 0 | BI19: 0 | BJ19: 0 | BK19: 0
A20: B1A19 | B20: S04M09 | D20: 0 | E20: 0 | F20: 1 | G20: 0 | H20: 0 | I20: 0 | J20: 0 | K20: 0 | L20: 0 | M20: 0 | N20: 0 | O20: 1 | P20: 0 | Q20: 0 | R20: 0 | S20: 0 | T20: 0 | U20: 0 | V20: 0 | W20: 0 | X20: 0 | Y20: 0 | Z20: 0 | AA20: 0 | AB20: 1 | AC20: 0 | AD20: 0 | AE20: 0 | AF20: 0 | AG20: 0 | AH20: 1 | AI20: 0 | AJ20: 0 | AK20: 0 | AL20: 0 | AM20: 0 | AN20: 0 | AO20: 0 | AP20: 0 | AQ20: 0 | AR20: 0 | AS20: 0 | AT20: 0 | AU20: 0 | AV20: 0 | AW20: 0 | AX20: 0 | AY20: 0 | AZ20: 0 | BA20: 0 | BB20: 0 | BC20: 0 | BD20: 0 | BE20: 0 | BF20: 0 | BG20: 0 | BH20: 0 | BI20: 0 | BJ20: 0 | BK20: 0
A21: B1A20 | B21: S16M08 | D21: 0 | E21: 0 | F21: 0 | G21: 0 | H21: 0 | I21: 0 | J21: 0 | K21: 0 | L21: 0 | M21: 0 | N21: 0 | O21: 0 | P21: 0 | Q21: 0 | R21: 0 | S21: 0 | T21: 1 | U21: 1 | V21: 0 | W21: 1 | X21: 1 | Y21: 1 | Z21: 0 | AA21: 0 | AB21: 0 | AC21: 0 | AD21: 0 | AE21: 1 | AF21: 1 | AG21: 0 | AH21: 0 | AI21: 0 | AJ21: 0 | AK21: 0 | AL21: 0 | AM21: 0 | AN21: 0 | AO21: 0 | AP21: 1 | AQ21: 0 | AR21: 1 | AS21: 0 | AT21: 0 | AU21: 0 | AV21: 1 | AW21: 0 | AX21: 1 | AY21: 0 | AZ21: 0 | BA21: 1 | BB21: 0 | BC21: 1 | BD21: 1 | BE21: 0 | BF21: 0 | BG21: 0 | BH21: 1 | BI21: 0 | BJ21: 1 | BK21: 0
A22: B1A21 | B22: S04M07 | D22: 0 | E22: 0 | F22: 0 | G22: 0 | H22: 0 | I22: 0 | J22: 0 | K22: 0 | L22: 1 | M22: 0 | N22: 0 | O22: 1 | P22: 0 | Q22: 0 | R22: 0 | S22: 0 | T22: 0 | U22: 0 | V22: 0 | W22: 0 | X22: 0 | Y22: 0 | Z22: 0 | AA22: 0 | AB22: 0 | AC22: 0 | AD22: 0 | AE22: 0 | AF22: 1 | AG22: 0 | AH22: 0 | AI22: 0 | AJ22: 0 | AK22: 0 | AL22: 0 | AM22: 1 | AN22: 0 | AO22: 0 | AP22: 0 | AQ22: 0 | AR22: 0 | AS22: 0 | AT22: 0 | AU22: 0 | AV22: 0 | AW22: 0 | AX22: 0 | AY22: 0 | AZ22: 0 | BA22: 0 | BB22: 0 | BC22: 0 | BD22: 0 | BE22: 0 | BF22: 0 | BG22: 0 | BH22: 0 | BI22: 0 | BJ22: 0 | BK22: 0
A23: B1A22 | B23: S60M01 | D23: 1 | E23: 1 | F23: 1 | G23: 1 | H23: 1 | I23: 1 | J23: 1 | K23: 1 | L23: 1 | M23: 1 | N23: 1 | O23: 1 | P23: 1 | Q23: 1 | R23: 1 | S23: 1 | T23: 1 | U23: 1 | V23: 1 | W23: 1 | X23: 1 | Y23: 1 | Z23: 1 | AA23: 1 | AB23: 1 | AC23: 1 | AD23: 1 | AE23: 1 | AF23: 1 | AG23: 1 | AH23: 1 | AI23: 1 | AJ23: 1 | AK23: 1 | AL23: 1 | AM23: 1 | AN23: 1 | AO23: 1 | AP23: 1 | AQ23: 1 | AR23: 1 | AS23: 1 | AT23: 1 | AU23: 1 | AV23: 1 | AW23: 1 | AX23: 1 | AY23: 1 | AZ23: 1 | BA23: 1 | BB23: 1 | BC23: 1 | BD23: 1 | BE23: 1 | BF23: 1 | BG23: 1 | BH23: 1 | BI23: 1 | BJ23: 1 | BK23: 1
... A29: B2A06 | B29: S04M08 | D29: 0 | E29: 0 | F29: 0 | G29: 0 | H29: 0 | I29: 0 | J29: 0 | K29: 0 | L29: 0 | M29: 0 | N29: 0 | O29: 0 | P29: 0 | Q29: 0 | R29: 0 | S29: 0 | T29: 0 | U29: 0 | V29: 0 | W29: 0 | X29: 0 | Y29: 1 | Z29: 0 | AA29: 0 | AB29: 0 | AC29: 0 | AD29: 1 | AE29: 0 | AF29: 0 | AG29: 0 | AH29: 0 | AI29: 0 | AJ29: 0 | AK29: 0 | AL29: 0 | AM29: 0 | AN29: 0 | AO29: 0 | AP29: 0 | AQ29: 0 | AR29: 0 | AS29: 0 | AT29: 0 | AU29: 0 | AV29: 0 | AW29: 0 | AX29: 0 | AY29: 0 | AZ29: 1 | BA29: 0 | BB29: 1 | BC29: 0 | BD29: 0 | BE29: 0 | BF29: 0 | BG29: 0 | BH29: 0 | BI29: 0 | BJ29: 0 | BK29: 0
A30: B2A07 | B30: S00M01 | C30: bare | D30: 0 | E30: 0 | F30: 0 | G30: 0 | H30: 0 | I30: 0 | J30: 0 | K30: 0 | L30: 0 | M30: 0 | N30: 0 | O30: 0 | P30: 0 | Q30: 0 | R30: 0 | S30: 0 | T30: 0 | U30: 0 | V30: 0 | W30: 0 | X30: 0 | Y30: 0 | Z30: 0 | AA30: 0 | AB30: 0 | AC30: 0 | AD30: 0 | AE30: 0 | AF30: 0 | AG30: 0 | AH30: 0 | AI30: 0 | AJ30: 0 | AK30: 0 | AL30: 0 | AM30: 0 | AN30: 0 | AO30: 0 | AP30: 0 | AQ30: 0 | AR30: 0 | AS30: 0 | AT30: 0 | AU30: 0 | AV30: 0 | AW30: 0 | AX30: 0 | AY30: 0 | AZ30: 0 | BA30: 0 | BB30: 0 | BC30: 0 | BD30: 0 | BE30: 0 | BF30: 0 | BG30: 0 | BH30: 0 | BI30: 0 | BJ30: 0 | BK30: 0
A31: B2A08 | B31: S02M11 | D31: 0 | E31: 0 | F31: 0 | G31: 0 | H31: 0 | I31: 0 | J31: 0 | K31: 0 | L31: 0 | M31: 0 | N31: 0 | O31: 0 | P31: 0 | Q31: 0 | R31: 0 | S31: 0 | T31: 0 | U31: 0 | V31: 0 | W31: 0 | X31: 0 | Y31: 0 | Z31: 0 | AA31: 0 | AB31: 0 | AC31: 0 | AD31: 0 | AE31: 0 | AF31: 0 | AG31: 0 | AH31: 0 | AI31: 0 | AJ31: 0 | AK31: 0 | AL31: 0 | AM31: 0 | AN31: 0 | AO31: 0 | AP31: 0 | AQ31: 0 | AR31: 0 | AS31: 0 | AT31: 0 | AU31: 0 | AV31: 1 | AW31: 0 | AX31: 0 | AY31: 0 | AZ31: 0 | BA31: 0 | BB31: 0 | BC31: 0 | BD31: 0 | BE31: 1 | BF31: 0 | BG31: 0 | BH31: 0 | BI31: 0 | BJ31: 0 | BK31: 0
A32: B2A09 | B32: S04M02 | D32: 0 | E32: 0 | F32: 0 | G32: 0 | H32: 0 | I32: 0 | J32: 0 | K32: 0 | L32: 0 | M32: 0 | N32: 0 | O32: 0 | P32: 0 | Q32: 0 | R32: 0 | S32: 0 | T32: 1 | U32: 0 | V32: 0 | W32: 0 | X32: 0 | Y32: 1 | Z32: 0 | AA32: 1 | AB32: 1 | AC32: 0 | AD32: 0 | AE32: 0 | AF32: 0 | AG32: 0 | AH32: 0 | AI32: 0 | AJ32: 0 | AK32: 0 | AL32: 0 | AM32: 0 | AN32: 0 | AO32: 0 | AP32: 0 | AQ32: 0 | AR32: 0 | AS32: 0 | AT32: 0 | AU32: 0 | AV32: 0 | AW32: 0 | AX32: 0 | AY32: 0 | AZ32: 0 | BA32: 0 | BB32: 0 | BC32: 0 | BD32: 0 | BE32: 0 | BF32: 0 | BG32: 0 | BH32: 0 | BI32: 0 | BJ32: 0 | BK32: 0
A33: B2A10 | B33: S16M01 | D33: 1 | E33: 1 | F33: 1 | G33: 0 | H33: 1 | I33: 0 | J33: 0 | K33: 0 | L33: 1 | M33: 0 | N33: 1 | O33: 0 | P33: 1 | Q33: 1 | R33: 0 | S33: 0 | T33: 0 | U33: 1 | V33: 0 | W33: 1 | X33: 1 | Y33: 1 | Z33: 0 | AA33: 1 | AB33: 1 | AC33: 1 | AD33: 0 | AE33: 1 | AF33: 0 | AG33: 0 | AH33: 0 | AI33: 0 | AJ33: 0 | AK33: 0 | AL33: 0 | AM33: 0 | AN33: 0 | AO33: 0 | AP33: 0 | AQ33: 0 | AR33: 0 | AS33: 0 | AT33: 0 | AU33: 0 | AV33: 0 | AW33: 0 | AX33: 0 | AY33: 0 | AZ33: 0 | BA33: 0 | BB33: 0 | BC33: 0 | BD33: 0 | BE33: 0 | BF33: 0 | BG33: 0 | BH33: 0 | BI33: 0 | BJ33: 0 | BK33: 0
A34: B2A11 | B34: S99M02 | C34: succ mow | D34: 0 | E34: 0 | F34: 0 | G34: 0 | H34: 0 | I34: 0 | J34: 0 | K34: 0 | L34: 0 | M34: 0 | N34: 0 | O34: 0 | P34: 0 | Q34: 0 | R34: 0 | S34: 0 | T34: 0 | U34: 0 | V34: 0 | W34: 0 | X34: 0 | Y34: 0 | Z34: 0 | AA34: 0 | AB34: 0 | AC34: 0 | AD34: 0 | AE34: 0 | AF34: 0 | AG34: 0 | AH34: 0 | AI34: 0 | AJ34: 0 | AK34: 0 | AL34: 0 | AM34: 0 | AN34: 0 | AO34: 0 | AP34: 0 | AQ34: 0 | AR34: 0 | AS34: 0 | AT34: 0 | AU34: 0 | AV34: 0 | AW34: 0 | AX34: 0 | AY34: 0 | AZ34: 0 | BA34: 0 | BB34: 0 | BC34: 0 | BD34: 0 | BE34: 0 | BF34: 0 | BG34: 0 | BH34: 0 | BI34: 0 | BJ34: 0 | BK34: 0
A35: B2A12 | B35: S08M03 | D35: 0 | E35: 0 | F35: 0 | G35: 0 | H35: 0 | I35: 0 | J35: 0 | K35: 0 | L35: 0 | M35: 0 | N35: 0 | O35: 0 | P35: 0 | Q35: 0 | R35: 0 | S35: 0 | T35: 0 | U35: 0 | V35: 0 | W35: 0 | X35: 0 | Y35: 0 | Z35: 0 | AA35: 0 | AB35: 0 | AC35: 0 | AD35: 0 | AE35: 0 | AF35: 0 | AG35: 1 | AH35: 0 | AI35: 0 | AJ35: 0 | AK35: 0 | AL35: 0 | AM35: 0 | AN35: 0 | AO35: 1 | AP35: 1 | AQ35: 1 | AR35: 1 | AS35: 1 | AT35: 0 | AU35: 0 | AV35: 1 | AW35: 0 | AX35: 1 | AY35: 0 | AZ35: 0 | BA35: 0 | BB35: 0 | BC35: 0 | BD35: 0 | BE35: 0 | BF35: 0 | BG35: 0 | BH35: 0 | BI35: 0 | BJ35: 0 | BK35: 0
A36: B2A13 | B36: S01M05 | D36: 0 | E36: 0 | F36: 0 | G36: 0 | H36: 0 | I36: 0 | J36: 0 | K36: 0 | L36: 0 | M36: 0 | N36: 0 | O36: 0 | P36: 0 | Q36: 0 | R36: 0 | S36: 0 | T36: 0 | U36: 0 | V36: 0 | W36: 0 | X36: 0 | Y36: 1 | Z36: 0 | AA36: 0 | AB36: 0 | AC36: 0 | AD36: 0 | AE36: 0 | AF36: 0 | AG36: 0 | AH36: 0 | AI36: 0 | AJ36: 0 | AK36: 0 | AL36: 0 | AM36: 0 | AN36: 0 | AO36: 0 | AP36: 0 | AQ36: 0 | AR36: 0 | AS36: 0 | AT36: 0 | AU36: 0 | AV36: 0 | AW36: 0 | AX36: 0 | AY36: 0 | AZ36: 0 | BA36: 0 | BB36: 0 | BC36: 0 | BD36: 0 | BE36: 0 | BF36: 0 | BG36: 0 | BH36: 0 | BI36: 0 | BJ36: 0 | BK36: 0
A37: B2A14 | B37: S08M13 | D37: 0 | E37: 0 | F37: 0 | G37: 0 | H37: 0 | I37: 0 | J37: 0 | K37: 0 | L37: 0 | M37: 0 | N37: 0 | O37: 1 | P37: 1 | Q37: 0 | R37: 0 | S37: 0 | T37: 0 | U37: 0 | V37: 0 | W37: 0 | X37: 1 | Y37: 0 | Z37: 0 | AA37: 0 | AB37: 0 | AC37: 0 | AD37: 0 | AE37: 1 | AF37: 0 | AG37: 0 | AH37: 0 | AI37: 0 | AJ37: 0 | AK37: 0 | AL37: 0 | AM37: 0 | AN37: 0 | AO37: 0 | AP37: 0 | AQ37: 0 | AR37: 1 | AS37: 0 | AT37: 0 | AU37: 0 | AV37: 0 | AW37: 0 | AX37: 1 | AY37: 0 | AZ37: 0 | BA37: 0 | BB37: 0 | BC37: 0 | BD37: 0 | BE37: 0 | BF37: 1 | BG37: 0 | BH37: 1 | BI37: 0 | BJ37: 0 | BK37: 0
A38: B2A15 | B38: S01M15 | D38: 0 | E38: 0 | F38: 0 | G38: 0 | H38: 0 | I38: 0 | J38: 0 | K38: 0 | L38: 0 | M38: 0 | N38: 0 | O38: 0 | P38: 0 | Q38: 0 | R38: 0 | S38: 0 | T38: 0 | U38: 0 | V38: 0 | W38: 0 | X38: 0 | Y38: 0 | Z38: 0 | AA38: 0 | AB38: 0 | AC38: 0 | AD38: 0 | AE38: 0 | AF38: 0 | AG38: 0 | AH38: 0 | AI38: 0 | AJ38: 0 | AK38: 0 | AL38: 0 | AM38: 0 | AN38: 0 | AO38: 0 | AP38: 0 | AQ38: 0 | AR38: 0 | AS38: 0 | AT38: 0 | AU38: 0 | AV38: 0 | AW38: 0 | AX38: 0 | AY38: 0 | AZ38: 0 | BA38: 0 | BB38: 0 | BC38: 0 | BD38: 1 | BE38: 0 | BF38: 0 | BG38: 0 | BH38: 0 | BI38: 0 | BJ38: 0 | BK38: 0
A39: B2A16 | B39: S04M12 | D39: 0 | E39: 0 | F39: 0 | G39: 0 | H39: 0 | I39: 0 | J39: 0 | K39: 0 | L39: 0 | M39: 0 | N39: 0 | O39: 0 | P39: 0 | Q39: 0 | R39: 0 | S39: 0 | T39: 0 | U39: 0 | V39: 0 | W39: 1 | X39: 0 | Y39: 0 | Z39: 1 | AA39: 0 | AB39: 0 | AC39: 0 | AD39: 0 | AE39: 0 | AF39: 0 | AG39: 0 | AH39: 0 | AI39: 0 | AJ39: 0 | AK39: 0 | AL39: 0 | AM39: 0 | AN39: 0 | AO39: 0 | AP39: 0 | AQ39: 0 | AR39: 1 | AS39: 0 | AT39: 0 | AU39: 0 | AV39: 0 | AW39: 0 | AX39: 0 | AY39: 0 | AZ39: 0 | BA39: 0 | BB39: 0 | BC39: 0 | BD39: 0 | BE39: 0 | BF39: 0 | BG39: 0 | BH39: 0 | BI39: 0 | BJ39: 0 | BK39: 1
A40: B2A17 | B40: S08M08 | D40: 0 | E40: 0 | F40: 0 | G40: 0 | H40: 0 | I40: 0 | J40: 0 | K40: 0 | L40: 0 | M40: 0 | N40: 0 | O40: 0 | P40: 0 | Q40: 0 | R40: 0 | S40: 0 | T40: 0 | U40: 0 | V40: 1 | W40: 1 | X40: 0 | Y40: 0 | Z40: 1 | AA40: 0 | AB40: 0 | AC40: 0 | AD40: 1 | AE40: 0 | AF40: 0 | AG40: 0 | AH40: 0 | AI40: 0 | AJ40: 0 | AK40: 0 | AL40: 0 | AM40: 0 | AN40: 0 | AO40: 0 | AP40: 0 | AQ40: 0 | AR40: 0 | AS40: 0 | AT40: 0 | AU40: 0 | AV40: 0 | AW40: 0 | AX40: 0 | AY40: 0 | AZ40: 1 | BA40: 0 | BB40: 0 | BC40: 0 | BD40: 0 | BE40: 1 | BF40: 0 | BG40: 1 | BH40: 0 | BI40: 0 | BJ40: 0 | BK40: 1
A41: B2A18 | B41: S16M11 | D41: 1 | E41: 0 | F41: 0 | G41: 0 | H41: 0 | I41: 1 | J41: 1 | K41: 0 | L41: 0 | M41: 0 | N41: 0 | O41: 0 | P41: 0 | Q41: 1 | R41: 0 | S41: 0 | T41: 1 | U41: 0 | V41: 0 | W41: 0 | X41: 0 | Y41: 0 | Z41: 1 | AA41: 1 | AB41: 0 | AC41: 1 | AD41: 0 | AE41: 0 | AF41: 0 | AG41: 1 | AH41: 1 | AI41: 1 | AJ41: 0 | AK41: 0 | AL41: 0 | AM41: 0 | AN41: 0 | AO41: 0 | AP41: 1 | AQ41: 0 | AR41: 0 | AS41: 0 | AT41: 0 | AU41: 0 | AV41: 0 | AW41: 0 | AX41: 0 | AY41: 0 | AZ41: 0 | BA41: 0 | BB41: 1 | BC41: 0 | BD41: 0 | BE41: 1 | BF41: 1 | BG41: 0 | BH41: 0 | BI41: 0 | BJ41: 1 | BK41: 0
A42: B2A19 | B42: S02M03 | D42: 0 | E42: 0 | F42: 0 | G42: 0 | H42: 0 | I42: 0 | J42: 0 | K42: 0 | L42: 0 | M42: 0 | N42: 0 | O42: 0 | P42: 0 | Q42: 0 | R42: 0 | S42: 0 | T42: 0 | U42: 0 | V42: 0 | W42: 0 | X42: 0 | Y42: 0 | Z42: 1 | AA42: 0 | AB42: 0 | AC42: 0 | AD42: 1 | AE42: 0 | AF42: 0 | AG42: 0 | AH42: 0 | AI42: 0 | AJ42: 0 | AK42: 0 | AL42: 0 | AM42: 0 | AN42: 0 | AO42: 0 | AP42: 0 | AQ42: 0 | AR42: 0 | AS42: 0 | AT42: 0 | AU42: 0 | AV42: 0 | AW42: 0 | AX42: 0 | AY42: 0 | AZ42: 0 | BA42: 0 | BB42: 0 | BC42: 0 | BD42: 0 | BE42: 0 | BF42: 0 | BG42: 0 | BH42: 0 | BI42: 0 | BJ42: 0 | BK42: 0
A43: B2A20 | B43: S02M16 | D43: 0 | E43: 0 | F43: 0 | G43: 0 | H43: 0 | I43: 0 | J43: 0 | K43: 0 | L43: 0 | M43: 0 | N43: 0 | O43: 0 | P43: 0 | Q43: 0 | R43: 0 | S43: 0 | T43: 0 | U43: 0 | V43: 0 | W43: 0 | X43: 0 | Y43: 1 | Z43: 0 | AA43: 0 | AB43: 0 | AC43: 0 | AD43: 0 | AE43: 0 | AF43: 0 | AG43: 0 | AH43: 0 | AI43: 0 | AJ43: 0 | AK43: 0 | AL43: 0 | AM43: 0 | AN43: 0 | AO43: 0 | AP43: 0 | AQ43: 0 | AR43: 0 | AS43: 0 | AT43: 0 | AU43: 0 | AV43: 0 | AW43: 0 | AX43: 0 | AY43: 0 | AZ43: 0 | BA43: 0 | BB43: 0 | BC43: 0 | BD43: 0 | BE43: 0 | BF43: 1 | BG43: 0 | BH43: 0 | BI43: 0 | BJ43: 0 | BK43: 0
A44: B2A21 | B44: S08M12 | D44: 0 | E44: 0 | F44: 0 | G44: 0 | H44: 0 | I44: 0 | J44: 0 | K44: 0 | L44: 0 | M44: 0 | N44: 0 | O44: 0 | P44: 0 | Q44: 0 | R44: 0 | S44: 0 | T44: 0 | U44: 0 | V44: 0 | W44: 0 | X44: 1 | Y44: 0 | Z44: 1 | AA44: 0 | AB44: 0 | AC44: 0 | AD44: 0 | AE44: 0 | AF44: 0 | AG44: 0 | AH44: 0 | AI44: 0 | AJ44: 0 | AK44: 0 | AL44: 0 | AM44: 1 | AN44: 0 | AO44: 1 | AP44: 0 | AQ44: 0 | AR44: 0 | AS44: 0 | AT44: 0 | AU44: 0 | AV44: 0 | AW44: 0 | AX44: 1 | AY44: 0 | AZ44: 0 | BA44: 1 | BB44: 1 | BC44: 0 | BD44: 1 | BE44: 0 | BF44: 0 | BG44: 0 | BH44: 0 | BI44: 0 | BJ44: 0 | BK44: 0
A45: B2A22 | B45: S16M06 | D45: 0 | E45: 0 | F45: 0 | G45: 0 | H45: 0 | I45: 0 | J45: 1 | K45: 0 | L45: 1 | M45: 0 | N45: 0 | O45: 0 | P45: 1 | Q45: 0 | R45: 1 | S45: 1 | T45: 0 | U45: 0 | V45: 0 | W45: 0 | X45: 0 | Y45: 0 | Z45: 0 | AA45: 0 | AB45: 0 | AC45: 0 | AD45: 0 | AE45: 0 | AF45: 1 | AG45: 0 | AH45: 1 | AI45: 0 | AJ45: 0 | AK45: 1 | AL45: 0 | AM45: 0 | AN45: 0 | AO45: 0 | AP45: 0 | AQ45: 0 | AR45: 0 | AS45: 0 | AT45: 0 | AU45: 0 | AV45: 0 | AW45: 1 | AX45: 1 | AY45: 0 | AZ45: 1 | BA45: 1 | BB45: 0 | BC45: 0 | BD45: 1 | BE45: 0 | BF45: 0 | BG45: 0 | BH45: 1 | BI45: 0 | BJ45: 1 | BK45: 1
...

Sheet PresenceAbsence kleine Plots
A1: plotcode | B1: mixcode | C1: Alo pra | D1: Ant odo | E1: Arr ela | F1: Ave pub | G1: Bro ere | H1: Bro hor | I1: Cyn cri | J1: Dac glo | K1: Fes pra | L1: Fes rub | M1: Hol lan | N1: Luz cam | O1: Phl pra | P1: Poa pra | Q1: Poa tri | R1: Tri fla | S1: Aju rep | T1: Bel per | U1: Gle hed | V1: Leo aut | W1: Leo his | X1: Pla lan | Y1: Pla med | Z1: Pri ver | AA1: Pru vul | AB1: Ran rep | AC1: Tar off | AD1: Ver cha | AE1: Ach mil | AF1: Ant syl | AG1: Cam pat | AH1: Car pra | AI1: Car car | AJ1: Cen jac | AK1: Cir ole | AL1: Cre bie | AM1: Dau car | AN1: Gal mol | AO1: Ger pra | AP1: Her sph | AQ1: Kna arv | AR1: Leu vul | AS1: Pas sat | AT1: Pim maj | AU1: Ran acr | AV1: Rum ace | AW1: San off | AX1: Tra pra | AY1: Lat pra | AZ1: Lot cor | BA1: Med lup | BB1: Med var | BC1: Ono vic | BD1: Tri cam | BE1: Tri dub | BF1: Tri fra | BG1: Tri hyb | BH1: Tri pra | BI1: Tri rep | BJ1: Vic cra
A2: B1B001 | B2: S02M03 | C2: 0 | D2: 0 | E2: 0 | F2: 0 | G2: 0 | H2: 0 | I2: 0 | J2: 0 | K2: 0 | L2: 0 | M2: 0 | N2: 0 | O2: 0 | P2: 0 | Q2: 0 | R2: 0 | S2: 0 | T2: 0 | U2: 0 | V2: 0 | W2: 0 | X2: 0 | Y2: 1 | Z2: 0 | AA2: 0 | AB2: 0 | AC2: 1 | AD2: 0 | AE2: 0 | AF2: 0 | AG2: 0 | AH2: 0 | AI2: 0 | AJ2: 0 | AK2: 0 | AL2: 0 | AM2: 0 | AN2: 0 | AO2: 0 | AP2: 0 | AQ2: 0 | AR2: 0 | AS2: 0 | AT2: 0 | AU2: 0 | AV2: 0 | AW2: 0 | AX2: 0 | AY2: 0 | AZ2: 0 | BA2: 0 | BB2: 0 | BC2: 0 | BD2: 0 | BE2: 0 | BF2: 0 | BG2: 0 | BH2: 0 | BI2: 0 | BJ2: 0
A3: B1B002 | B3: S01M09 | C3: 0 | D3: 0 | E3: 0 | F3: 0 | G3: 0 | H3: 0 | I3: 0 | J3: 0 | K3: 0 | L3: 0 | M3: 0 | N3: 0 | O3: 0 | P3: 0 | Q3: 0 | R3: 0 | S3: 0 | T3: 0 | U3: 0 | V3: 0 | W3: 0 | X3: 0 | Y3: 0 | Z3: 0 | AA3: 0 | AB3: 0 | AC3: 0 | AD3: 0 | AE3: 0 | AF3: 0 | AG3: 0 | AH3: 0 | AI3: 0 | AJ3: 0 | AK3: 1 | AL3: 0 | AM3: 0 | AN3: 0 | AO3: 0 | AP3: 0 | AQ3: 0 | AR3: 0 | AS3: 0 | AT3: 0 | AU3: 0 | AV3: 0 | AW3: 0 | AX3: 0 | AY3: 0 | AZ3: 0 | BA3: 0 | BB3: 0 | BC3: 0 | BD3: 0 | BE3: 0 | BF3: 0 | BG3: 0 | BH3: 0 | BI3: 0 | BJ3: 0
A4: B1B003 | B4: S06M06 | C4: 1 | D4: 0 | E4: 1 | F4: 0 | G4: 0 | H4: 0 | I4: 0 | J4: 0 | K4: 0 | L4: 0 | M4: 0 | N4: 0 | O4: 1 | P4: 0 | Q4: 1 | R4: 0 | S4: 0 | T4: 0 | U4: 0 | V4: 0 | W4: 0 | X4: 0 | Y4: 0 | Z4: 0 | AA4: 0 | AB4: 0 | AC4: 0 | AD4: 0 | AE4: 0 | AF4: 1 | AG4: 0 | AH4: 0 | AI4: 0 | AJ4: 0 | AK4: 0 | AL4: 0 | AM4: 0 | AN4: 0 | AO4: 0 | AP4: 0 | AQ4: 0 | AR4: 0 | AS4: 0 | AT4: 0 | AU4: 0 | AV4: 0 | AW4: 0 | AX4: 0 | AY4: 0 | AZ4: 0 | BA4: 0 | BB4: 0 | BC4: 0 | BD4: 0 | BE4: 0 | BF4: 0 | BG4: 0 | BH4: 0 | BI4: 1 | BJ4: 0
A5: B1B004 | B5: S03M12 | C5: 1 | D5: 0 | E5: 0 | F5: 0 | G5: 0 | H5: 0 | I5: 0 | J5: 1 | K5: 0 | L5: 0 | M5: 0 | N5: 0 | O5: 0 | P5: 0 | Q5: 0 | R5: 0 | S5: 0 | T5: 0 | U5: 0 | V5: 0 | W5: 0 | X5: 0 | Y5: 0 | Z5: 0 | AA5: 0 | AB5: 0 | AC5: 0 | AD5: 0 | AE5: 0 | AF5: 0 | AG5: 0 | AH5: 0 | AI5: 0 | AJ5: 0 | AK5: 0 | AL5: 0 | AM5: 0 | AN5: 0 | AO5: 0 | AP5: 0 | AQ5: 0 | AR5: 0 | AS5: 0 | AT5: 0 | AU5: 0 | AV5: 0 | AW5: 0 | AX5: 0 | AY5: 0 | AZ5: 0 | BA5: 0 | BB5: 0 | BC5: 0 | BD5: 0 | BE5: 0 | BF5: 0 | BG5: 0 | BH5: 1 | BI5: 0 | BJ5: 0
A6: B1B005 | B6: S01M51 | C6: 0 | D6: 0 | E6: 0 | F6: 0 | G6: 0 | H6: 0 | I6: 0 | J6: 0 | K6: 0 | L6: 0 | M6: 0 | N6: 0 | O6: 0 | P6: 0 | Q6: 0 | R6: 0 | S6: 0 | T6: 0 | U6: 0 | V6: 0 | W6: 0 | X6: 0 | Y6: 0 | Z6: 0 | AA6: 0 | AB6: 0 | AC6: 0 | AD6: 0 | AE6: 0 | AF6: 0 | AG6: 0 | AH6: 0 | AI6: 0 | AJ6: 0 | AK6: 0 | AL6: 0 | AM6: 0 | AN6: 0 | AO6: 0 | AP6: 0 | AQ6: 0 | AR6: 0 | AS6: 0 | AT6: 0 | AU6: 0 | AV6: 1 | AW6: 0 | AX6: 0 | AY6: 0 | AZ6: 0 | BA6: 0 | BB6: 0 | BC6: 0 | BD6: 0 | BE6: 0 | BF6: 0 | BG6: 0 | BH6: 0 | BI6: 0 | BJ6: 0
A7: B1B006 | B7: S03M01 | C7: 0 | D7: 0 | E7: 1 | F7: 0 | G7: 0 | H7: 0 | I7: 0 | J7: 1 | K7: 0 | L7: 0 | M7: 0 | N7: 0 | O7: 0 | P7: 0 | Q7: 0 | R7: 0 | S7: 0 | T7: 0 | U7: 0 | V7: 0 | W7: 0 | X7: 0 | Y7: 0 | Z7: 0 | AA7: 0 | AB7: 0 | AC7: 0 | AD7: 0 | AE7: 0 | AF7: 1 | AG7: 0 | AH7: 0 | AI7: 0 | AJ7: 0 | AK7: 0 | AL7: 0 | AM7: 0 | AN7: 0 | AO7: 0 | AP7: 0 | AQ7: 0 | AR7: 0 | AS7: 0 | AT7: 0 | AU7: 0 | AV7: 0 | AW7: 0 | AX7: 0 | AY7: 0 | AZ7: 0 | BA7: 0 | BB7: 0 | BC7: 0 | BD7: 0 | BE7: 0 | BF7: 0 | BG7: 0 | BH7: 0 | BI7: 0 | BJ7: 0
A8: B1B007 | B8: S02M52 | C8: 0 | D8: 0 | E8: 0 | F8: 0 | G8: 0 | H8: 0 | I8: 0 | J8: 0 | K8: 0 | L8: 0 | M8: 0 | N8: 0 | O8: 0 | P8: 0 | Q8: 0 | R8: 0 | S8: 0 | T8: 0 | U8: 0 | V8: 0 | W8: 0 | X8: 0 | Y8: 0 | Z8: 0 | AA8: 0 | AB8: 0 | AC8: 0 | AD8: 0 | AE8: 0 | AF8: 0 | AG8: 0 | AH8: 0 | AI8: 0 | AJ8: 0 | AK8: 0 | AL8: 0 | AM8: 0 | AN8: 0 | AO8: 0 | AP8: 0 | AQ8: 0 | AR8: 0 | AS8: 0 | AT8: 0 | AU8: 0 | AV8: 0 | AW8: 0 | AX8: 0 | AY8: 0 | AZ8: 0 | BA8: 0 | BB8: 0 | BC8: 0 | BD8: 0 | BE8: 0 | BF8: 0 | BG8: 0 | BH8: 1 | BI8: 1 | BJ8: 0
A9: B1B008 | B9: S03M24 | C9: 0 | D9: 0 | E9: 0 | F9: 0 | G9: 0 | H9: 0 | I9: 0 | J9: 0 | K9: 0 | L9: 0 | M9: 0 | N9: 0 | O9: 0 | P9: 0 | Q9: 1 | R9: 0 | S9: 0 | T9: 0 | U9: 0 | V9: 0 | W9: 0 | X9: 0 | Y9: 0 | Z9: 0 | AA9: 0 | AB9: 0 | AC9: 0 | AD9: 0 | AE9: 0 | AF9: 0 | AG9: 0 | AH9: 0 | AI9: 0 | AJ9: 0 | AK9: 0 | AL9: 0 | AM9: 0 | AN9: 0 | AO9: 0 | AP9: 0 | AQ9: 0 | AR9: 0 | AS9: 0 | AT9: 0 | AU9: 0 | AV9: 0 | AW9: 0 | AX9: 0 | AY9: 0 | AZ9: 0 | BA9: 0 | BB9: 0 | BC9: 0 | BD9: 0 | BE9: 0 | BF9: 0 | BG9: 0 | BH9: 1 | BI9: 1 | BJ9: 0
A10: B1B009 | B10: S02M24 | C10: 0 | D10: 0 | E10: 0 | F10: 0 | G10: 0 | H10: 0 | I10: 0 | J10: 0 | K10: 0 | L10: 0 | M10: 0 | N10: 0 | O10: 0 | P10: 0 | Q10: 0 | R10: 0 | S10: 0 | T10: 0 | U10: 0 | V10: 0 | W10: 0 | X10: 0 | Y10: 0 | Z10: 0 | AA10: 0 | AB10: 0 | AC10: 0 | AD10: 0 | AE10: 0 | AF10: 1 | AG10: 0 | AH10: 0 | AI10: 0 | AJ10: 0 | AK10: 0 | AL10: 0 | AM10: 0 | AN10: 0 | AO10: 1 | AP10: 0 | AQ10: 0 | AR10: 0 | AS10: 0 | AT10: 0 | AU10: 0 | AV10: 0 | AW10: 0 | AX10: 0 | AY10: 0 | AZ10: 0 | BA10: 0 | BB10: 0 | BC10: 0 | BD10: 0 | BE10: 0 | BF10: 0 | BG10: 0 | BH10: 0 | BI10: 0 | BJ10: 0
A11: B1B010 | B11: S06M03 | C11: 1 | D11: 0 | E11: 1 | F11: 0 | G11: 0 | H11: 0 | I11: 0 | J11: 1 | K11: 0 | L11: 0 | M11: 0 | N11: 0 | O11: 1 | P11: 0 | Q11: 1 | R11: 0 | S11: 0 | T11: 0 | U11: 0 | V11: 0 | W11: 0 | X11: 0 | Y11: 0 | Z11: 0 | AA11: 0 | AB11: 0 | AC11: 0 | AD11: 0 | AE11: 0 | AF11: 0 | AG11: 0 | AH11: 0 | AI11: 0 | AJ11: 0 | AK11: 0 | AL11: 0 | AM11: 0 | AN11: 0 | AO11: 0 | AP11: 0 | AQ11: 0 | AR11: 0 | AS11: 0 | AT11: 0 | AU11: 0 | AV11: 0 | AW11: 0 | AX11: 0 | AY11: 0 | AZ11: 0 | BA11: 0 | BB11: 0 | BC11: 0 | BD11: 0 | BE11: 0 | BF11: 0 | BG11: 0 | BH11: 1 | BI11: 0 | BJ11: 0
A12: B1B011 | B12: S06M07 | C12: 0 | D12: 0 | E12: 0 | F12: 0 | G12: 0 | H12: 0 | I12: 0 | J12: 1 | K12: 0 | L12: 0 | M12: 0 | N12: 0 | O12: 1 | P12: 0 | Q12: 1 | R12: 0 | S12: 0 | T12: 0 | U12: 0 | V12: 0 | W12: 0 | X12: 0 | Y12: 0 | Z12: 0 | AA12: 0 | AB12: 0 | AC12: 0 | AD12: 0 | AE12: 0 | AF12: 1 | AG12: 0 | AH12: 0 | AI12: 0 | AJ12: 0 | AK12: 0 | AL12: 0 | AM12: 0 | AN12: 0 | AO12: 1 | AP12: 0 | AQ12: 0 | AR12: 0 | AS12: 0 | AT12: 0 | AU12: 0 | AV12: 0 | AW12: 0 | AX12: 0 | AY12: 0 | AZ12: 0 | BA12: 0 | BB12: 0 | BC12: 0 | BD12: 0 | BE12: 0 | BF12: 0 | BG12: 0 | BH12: 0 | BI12: 1 | BJ12: 0
A13: B1B012 | B13: S02M37 | C13: 0 | D13: 0 | E13: 0 | F13: 0 | G13: 0 | H13: 0 | I13: 0 | J13: 0 | K13: 0 | L13: 0 | M13: 0 | N13: 0 | O13: 1 | P13: 0 | Q13: 1 | R13: 0 | S13: 0 | T13: 0 | U13: 0 | V13: 0 | W13: 0 | X13: 0 | Y13: 0 | Z13: 0 | AA13: 0 | AB13: 0 | AC13: 0 | AD13: 0 | AE13: 0 | AF13: 0 | AG13: 0 | AH13: 0 | AI13: 0 | AJ13: 0 | AK13: 0 | AL13: 0 | AM13: 0 | AN13: 0 | AO13: 0 | AP13: 0 | AQ13: 0 | AR13: 0 | AS13: 0 | AT13: 0 | AU13: 0 | AV13: 0 | AW13: 0 | AX13: 0 | AY13: 0 | AZ13: 0 | BA13: 0 | BB13: 0 | BC13: 0 | BD13: 0 | BE13: 0 | BF13: 0 | BG13: 0 | BH13: 0 | BI13: 0 | BJ13: 0
... A406: B4B100 | B406: S01M63 | C406: 0 | D406: 0 | E406: 0 | F406: 0 | G406: 0 | H406: 0 | I406: 0 | J406: 0 | K406: 0 | L406: 0 | M406: 0 | N406: 0 | O406: 0 | P406: 0 | Q406: 0 | R406: 0 | S406: 0 | T406: 0 | U406: 0 | V406: 0 | W406: 0 | X406: 0 | Y406: 0 | Z406: 0 | AA406: 0 | AB406: 0 | AC406: 0 | AD406: 0 | AE406: 0 | AF406: 0 | AG406: 0 | AH406: 0 | AI406: 0 | AJ406: 0 | AK406: 0 | AL406: 0 | AM406: 0 | AN406: 0 | AO406: 0 | AP406: 0 | AQ406: 0 | AR406: 0 | AS406: 0 | AT406: 0 | AU406: 0 | AV406: 0 | AW406: 0 | AX406: 0 | AY406: 0 | AZ406: 0 | BA406: 0 | BB406: 0 | BC406: 0 | BD406: 0 | BE406: 0 | BF406: 0 | BG406: 0 | BH406: 0 | BI406: 0 | BJ406: 0

Sheet Plotinformation große Plots
A1: plotcode | B1: mixcode | C1: block | D1: plot | E1: sowndiv | F1: funcgr | G1: numgrass | H1: numsherb | I1: numtherb | J1: numleg | K1: grass | L1: sherb | M1: therb | N1: leg
A2: B1A01 | B2: S16M12 | C2: B1 | D2: =RIGHT(A2,3) -> A01 | E2: 16 | F2: =SUM(K2:N2) -> 4 | G2: 4 | H2: 4 | I2: 4 | J2: 4 | K2: 1 | L2: 1 | M2: 1 | N2: 1
A3: B1A02 | B3: S08M07 | C3: B1 | D3: =RIGHT(A3,3) -> A02 | E3: 8 | F3: =SUM(K3:N3) -> 2 | G3: 4 | H3: 0 | I3: 4 | J3: 0 | K3: 1 | L3: 0 | M3: 1 | N3: 0
A4: B1A03 | B4: S08M11 | C4: B1 | D4: =RIGHT(A4,3) -> A03 | E4: 8 | F4: =SUM(K4:N4) -> 3 | G4: 3 | H4: 3 | I4: 0 | J4: 2 | K4: 1 | L4: 1 | M4: 0 | N4: 1
A5: B1A04 | B5: S04M16 | C5: B1 | D5: =RIGHT(A5,3) -> A04 | E5: 4 | F5: =SUM(K5:N5) -> 4 | G5: 1 | H5: 1 | I5: 1 | J5: 1 | K5: 1 | L5: 1 | M5: 1 | N5: 1
A6: B1A05 | B6: S02M07 | C6: B1 | D6: =RIGHT(A6,3) -> A05 | E6: 2 | F6: =SUM(K6:N6) -> 1 | G6: 0 | H6: 0 | I6: 0 | J6: 2 | K6: 0 | L6: 0 | M6: 0 | N6: 1
A7: B1A06 | B7: S16M03 | C7: B1 | D7: =RIGHT(A7,3) -> A06 | E7: 16 | F7: =SUM(K7:N7) -> 2 | G7: 8 | H7: 0 | I7: 8 | J7: 0 | K7: 1 | L7: 0 | M7: 1 | N7: 0
A8: B1A07 | B8: S02M06 | C8: B1 | D8: =RIGHT(A8,3) -> A07 | E8: 2 | F8: =SUM(K8:N8) -> 1 | G8: 0 | H8: 0 | I8: 2 | J8: 0 | K8: 0 | L8: 0 | M8: 1 | N8: 0
A9: B1A08 | B9: S01M16 | C9: B1 | D9: =RIGHT(A9,3) -> A08 | E9: 1 | F9: =SUM(K9:N9) -> 1 | G9: 0 | H9: 0 | I9: 0 | J9: 1 | K9: 0 | L9: 0 | M9: 0 | N9: 1
A10: B1A09 | B10: S01M01 | C10: B1 | D10: =RIGHT(A10,3) -> A09 | E10: 1 | F10: =SUM(K10:N10) -> 1 | G10: 1 | H10: 0 | I10: 0 | J10: 0 | K10: 1 | L10: 0 | M10: 0 | N10: 0
A11: B1A10 | B11: S00M01 | C11: B1 | D11: =RIGHT(A11,3) -> A10 | E11: 0 | F11: =SUM(K11:N11) -> 0 | G11: 0 | H11: 0 | I11: 0 | J11: 0 | K11: 0 | L11: 0 | M11: 0 | N11: 0
A12: B1A11 | B12: S16M14 | C12: B1 | D12: =RIGHT(A12,3) -> A11 | E12: 16 | F12: =SUM(K12:N12) -> 1 | G12: 0 | H12: 0 | I12: 16 | J12: 0 | K12: 0 | L12: 0 | M12: 1 | N12: 0
A13: B1A12 | B13: S08M04 | C13: B1 | D13: =RIGHT(A13,3) -> A12 | E13: 8 | F13: =SUM(K13:N13) -> 1 | G13: 0 | H13: 0 | I13: 0 | J13: 8 | K13: 0 | L13: 0 | M13: 0 | N13: 1
... A93: B4A23 | B93: S99M03 | C93: B4 | D93: =RIGHT(A93,3) -> A23 | E93: 0 | F93: =SUM(K93:N93) -> 0 | G93: 0 | H93: 0 | I93: 0 | J93: 0 | K93: 0 | L93: 0 | M93: 0 | N93: 0

Sheet Plotinformation kleine Plots
A1: plotcode | B1: mixcode | C1: block | D1: plot | E1: Monoculture | F1: Replication | G1: Evenness | H1: Dominanz | I1: sowndiv | J1: funcgr | K1: numgrass | L1: numsherb | M1: numtherb | N1: numleg | O1: grass | P1: sherb | Q1: therb | R1: leg
A2: B1B001 | B2: S02M03 | C2: =LEFT(A2,2) -> B1 | D2: =RIGHT(A2,4) -> B001 | E2: 0 | F2: 1 | G2: 1 | H2: 0 | I2: 2 | J2: =P2+Q2+R2+'PresenceAbsence kleine Plots'!C2 -> 1 | K2: 0 | L2: 2 | M2: 0 | N2: 0 | O2: 0 | P2: 1 | Q2: 0 | R2: 0
A3: B1B002 | B3: S01M09 | C3: =LEFT(A3,2) -> B1 | D3: =RIGHT(A3,4) -> B002 | E3: 1 | F3: 1 | G3: 1 | H3: 0 | I3: 1 | J3: =P3+Q3+R3+'PresenceAbsence kleine Plots'!C3 -> 1 | K3: 0 | L3: 0 | M3: 1 | N3: 0 | O3: 0 | P3: 0 | Q3: 1 | R3: 0
A4: B1B003 | B4: S06M06 | C4: =LEFT(A4,2) -> B1 | D4: =RIGHT(A4,4) -> B003 | E4: 0 | F4: 0 | G4: 0 | H4: 1 | I4: 6 | J4: =P4+Q4+R4+'PresenceAbsence kleine Plots'!C4 -> 3 | K4: 4 | L4: 0 | M4: 1 | N4: 1 | O4: 1 | P4: 0 | Q4: 1 | R4: 1
A5: B1B004 | B5: S03M12 | C5: =LEFT(A5,2) -> B1 | D5: =RIGHT(A5,4) -> B004 | E5: 0 | F5: 0 | G5: 0 | H5: 1 | I5: 3 | J5: =P5+Q5+R5+'PresenceAbsence kleine Plots'!C5 -> 2 | K5: 2 | L5: 0 | M5: 0 | N5: 1 | O5: 1 | P5: 0 | Q5: 0 | R5: 1
A6: B1B005 | B6: S01M51 | C6: =LEFT(A6,2) -> B1 | D6: =RIGHT(A6,4) -> B005 | E6: 1 | F6: 0 | G6: 0 | H6: 0 | I6: 1 | J6: =P6+Q6+R6+'PresenceAbsence kleine Plots'!C6 -> 1 | K6: 0 | L6: 0 | M6: 1 | N6: 0 | O6: 0 | P6: 0 | Q6: 1 | R6: 0
A7: B1B006 | B7: S03M01 | C7: =LEFT(A7,2) -> B1 | D7: =RIGHT(A7,4) -> B006 | E7: 0 | F7: 0 | G7: 0 | H7: 1 | I7: 3 | J7: 2 | K7: 2 | L7: 0 | M7: 1 | N7: 0 | O7: 1 | P7: 0 | Q7: 1 | R7: 0
A8: B1B007 | B8: S02M52 | C8: =LEFT(A8,2) -> B1 | D8: =RIGHT(A8,4) -> B007 | E8: 0 | F8: 0 | G8: 0 | H8: 1 | I8: 2 | J8: =P8+Q8+R8+'PresenceAbsence kleine Plots'!C8 -> 1 | K8: 0 | L8: 0 | M8: 0 | N8: 2 | O8: 0 | P8: 0 | Q8: 0 | R8: 1
A9: B1B008 | B9: S03M24 | C9: =LEFT(A9,2) -> B1 | D9: =RIGHT(A9,4) -> B008 | E9: 0 | F9: 0 | G9: 0 | H9: 1 | I9: 3 | J9: 2 | K9: 1 | L9: 0 | M9: 0 | N9: 2 | O9: 1 | P9: 0 | Q9: 0 | R9: 1
A10: B1B009 | B10: S02M24 | C10: =LEFT(A10,2) -> B1 | D10: =RIGHT(A10,4) -> B009 | E10: 0 | F10: 0 | G10: 0 | H10: 1 | I10: 2 | J10: =P10+Q10+R10+'PresenceAbsence kleine Plots'!C10 -> 1 | K10: 0 | L10: 0 | M10: 2 | N10: 0 | O10: 0 | P10: 0 | Q10: 1 | R10: 0
A11: B1B010 | B11: S06M03 | C11: =LEFT(A11,2) -> B1 | D11: =RIGHT(A11,4) -> B010 | E11: 0 | F11: 0 | G11: 0 | H11: 1 | I11: 6 | J11: =P11+Q11+R11+'PresenceAbsence kleine Plots'!C11 -> 2 | K11: 5 | L11: 0 | M11: 0 | N11: 1 | O11: 1 | P11: 0 | Q11: 0 | R11: 1
A12: B1B011 | B12: S06M07 | C12: =LEFT(A12,2) -> B1 | D12: =RIGHT(A12,4) -> B011 | E12: 0 | F12: 0 | G12: 0 | H12: 1 | I12: 6 | J12: 3 | K12: 3 | L12: 0 | M12: 2 | N12: 1 | O12: 1 | P12: 0 | Q12: 1 | R12: 1
A13: B1B012 | B13: S02M37 | C13: =LEFT(A13,2) -> B1 | D13: =RIGHT(A13,4) -> B012 | E13: 0 | F13: 0 | G13: 0 | H13: 1 | I13: 2 | J13: 1 | K13: 2 | L13: 0 | M13: 0 | N13: 0 | O13: 1 | P13: 0 | Q13: 0 | R13: 0
A14: B1B013 | B14: S16M01 | C14: =LEFT(A14,2) -> B1 | D14: =RIGHT(A14,4) -> B013 | E14: 0 | F14: 1 | G14: 1 | H14: 0 | I14: 16 | J14: =P14+Q14+R14+'PresenceAbsence kleine Plots'!C14 -> 2 | K14: 8 | L14: 8 | M14: 0 | N14: 0 | O14: 1 | P14: 1 | Q14: 0 | R14: 0
A15: B1B014 | B15: S02M09 | C15: =LEFT(A15,2) -> B1 | D15: =RIGHT(A15,4) -> B014 | E15: 0 | F15: 1 | G15: 1 | H15: 0 | I15: 2 | J15: 2 | K15: 1 | L15: 1 | M15: 0 | N15: 0 | O15: 1 | P15: 1 | Q15: 0 | R15: 0
A16: B1B015 | B16: S16M08 | C16: =LEFT(A16,2) -> B1 | D16: =RIGHT(A16,4) -> B015 | E16: 0 | F16: 1 | G16: 1 | H16: 0 | I16: 16 | J16: =P16+Q16+R16+'PresenceAbsence kleine Plots'!C16 -> 3 | K16: 0 | L16: 6 | M16: 5 | N16: 5 | O16: 0 | P16: 1 | Q16: 1 | R16: 1
A17: B1B016 | B17: S02M39 | C17: =LEFT(A17,2) -> B1 | D17: =RIGHT(A17,4) -> B016 | E17: 0 | F17: 0 | G17: 0 | H17: 1 | I17: 2 | J17: =P17+Q17+R17+'PresenceAbsence kleine Plots'!C17 -> 2 | K17: 0 | L17: 0 | M17: 1 | N17: 1 | O17: 0 | P17: 0 | Q17: 1 | R17: 1
A18: B1B017 | B18: S04M20 | C18: =LEFT(A18,2) -> B1 | D18: =RIGHT(A18,4) -> B017 | E18: 0 | F18: 0 | G18: 0 | H18: 1 | I18: 4 | J18: 2 | K18: 3 | L18: 0 | M18: 1 | N18: 0 | O18: 1 | P18: 0 | Q18: 1 | R18: 0
A19: B1B018 | B19: S08M03 | C19: =LEFT(A19,2) -> B1 | D19: =RIGHT(A19,4) -> B018 | E19: 0 | F19: 1 | G19: 1 | H19: 0 | I19: 8 | J19: =P19+Q19+R19+'PresenceAbsence kleine Plots'!C19 -> 1 | K19: 0 | L19: 0 | M19: 8 | N19: 0 | O19: 0 | P19: 0 | Q19: 1 | R19: 0
A20: B1B019 | B20: S03M10 | C20: =LEFT(A20,2) -> B1 | D20: =RIGHT(A20,4) -> B019 | E20: 0 | F20: 0 | G20: 0 | H20: 1 | I20: 3 | J20: 1 | K20: 3 | L20: 0 | M20: 0 | N20: 0 | O20: 1 | P20: 0 | Q20: 0 | R20: 0
A21: B1B020 | B21: S01M31 | C21: =LEFT(A21,2) -> B1 | D21: =RIGHT(A21,4) -> B020 | E21: 1 | F21: 0 | G21: 0 | H21: 0 | I21: 1 | J21: =P21+Q21+R21+'PresenceAbsence kleine Plots'!C21 -> 1 | K21: 0 | L21: 0 | M21: 1 | N21: 0 | O21: 0 | P21: 0 | Q21: 1 | R21: 0
A22: B1B021 | B22: S04M33 | C22: =LEFT(A22,2) -> B1 | D22: =RIGHT(A22,4) -> B021 | E22: 0 | F22: 0 | G22: 0 | H22: 1 | I22: 4 | J22: =P22+Q22+R22+'PresenceAbsence kleine Plots'!C22 -> 2 | K22: 2 | L22: 0 | M22: 0 | N22: 2 | O22: 1 | P22: 0 | Q22: 0 | R22: 1
A23: B1B022 | B23: S01M47 | C23: =LEFT(A23,2) -> B1 | D23: =RIGHT(A23,4) -> B022 | E23: 1 | F23: 0 | G23: 0 | H23: 1 | I23: 1 | J23: 1 | K23: 1 | L23: 0 | M23: 0 | N23: 0 | O23: 1 | P23: 0 | Q23: 0 | R23: 0
A24: B1B023 | B24: S02M48 | C24: =LEFT(A24,2) -> B1 | D24: =RIGHT(A24,4) -> B023 | E24: 0 | F24: 0 | G24: 0 | H24: 1 | I24: 2 | J24: 2 | K24: 1 | L24: 0 | M24: 0 | N24: 1 | O24: 1 | P24: 0 | Q24: 0 | R24: 1
A25: B1B024 | B25: S03M18 | C25: =LEFT(A25,2) -> B1 | D25: =RIGHT(A25,4) -> B024 | E25: 0 | F25: 0 | G25: 0 | H25: 1 | I25: 3 | J25: =P25+Q25+R25+'PresenceAbsence kleine Plots'!C25 -> 2 | K25: 2 | L25: 0 | M25: 0 | N25: 1 | O25: 1 | P25: 0 | Q25: 0 | R25: 1
A26: B1B025 | B26: S01M60 | C26: =LEFT(A26,2) -> B1 | D26: =RIGHT(A26,4) -> B025 | E26: 1 | F26: 0 | G26: 0 | H26: 1 | I26: 1 | J26: =P26+Q26+R26+'PresenceAbsence kleine Plots'!C26 -> 1 | K26: 0 | L26: 0 | M26: 0 | N26: 1 | O26: 0 | P26: 0 | Q26: 0 | R26: 1
A27: B1B026 | B27: S02M43 | C27: =LEFT(A27,2) -> B1 | D27: =RIGHT(A27,4) -> B026 | E27: 0 | F27: 0 | G27: 0 | H27: 1 | I27: 2 | J27: 2 | K27: 1 | L27: 0 | M27: 0 | N27: 1 | O27: 1 | P27: 0 | Q27: 0 | R27: 1
A28: B1B027 | B28: S04M07 | C28: =LEFT(A28,2) -> B1 | D28: =RIGHT(A28,4) -> B027 | E28: 0 | F28: 1 | G28: 1 | H28: 0 | I28: 4 | J28: 2 | K28: 2 | L28: 0 | M28: 2 | N28: 0 | O28: 1 | P28: 0 | Q28: 1 | R28: 0
A29: B1B028 | B29: S02M26 | C29: =LEFT(A29,2) -> B1 | D29: =RIGHT(A29,4) -> B028 | E29: 0 | F29: 0 | G29: 0 | H29: 1 | I29: 2 | J29: 2 | K29: 1 | L29: 0 | M29: 1 | N29: 0 | O29: 1 | P29: 0 | Q29: 1 | R29: 0
A30: B1B029 | B30: S02M15 | C30: =LEFT(A30,2) -> B1 | D30: =RIGHT(A30,4) -> B029 | E30: 0 | F30: 1 | G30: 1 | H30: 0 | I30: 2 | J30: =P30+Q30+R30+'PresenceAbsence kleine Plots'!C30 -> 2 | K30: 0 | L30: 1 | M30: 0 | N30: 1 | O30: 0 | P30: 1 | Q30: 0 | R30: 1
A31: B1B030 | B31: S08M12 | C31: =LEFT(A31,2) -> B1 | D31: =RIGHT(A31,4) -> B030 | E31: 0 | F31: 1 | G31: 1 | H31: 0 | I31: 8 | J31: =P31+Q31+R31+'PresenceAbsence kleine Plots'!C31 -> 3 | K31: 0 | L31: 2 | M31: 3 | N31: 3 | O31: 0 | P31: 1 | Q31: 1 | R31: 1
A32: B1B031 | B32: S09M01 | C32: =LEFT(A32,2) -> B1 | D32: =RIGHT(A32,4) -> B031 | E32: 0 | F32: 0 | G32: 0 | H32: 1 | I32: 9 | J32: =P32+Q32+R32+'PresenceAbsence kleine Plots'!C32 -> 3 | K32: 5 | L32: 0 | M32: 2 | N32: 2 | O32: 1 | P32: 0 | Q32: 1 | R32: 1
A33: B1B032 | B33: S01M28 | C33: =LEFT(A33,2) -> B1 | D33: =RIGHT(A33,4) -> B032 | E33: 1 | F33: 0 | G33: 0 | H33: 0 | I33: 1 | J33: =P33+Q33+R33+'PresenceAbsence kleine Plots'!C33 -> 1 | K33: 0 | L33: 0 | M33: 1 | N33: 0 | O33: 0 | P33: 0 | Q33: 1 | R33: 0
A34: B1B033 | B34: S01M57 | C34: =LEFT(A34,2) -> B1 | D34: =RIGHT(A34,4) -> B033 | E34: 1 | F34: 0 | G34: 0 | H34: 0 | I34: 1 | J34: 1 | K34: 1 | L34: 0 | M34: 0 | N34: 0 | O34: 1 | P34: 0 | Q34: 0 | R34: 0
A35: B1B034 | B35: S04M22 | C35: =LEFT(A35,2) -> B1 | D35: =RIGHT(A35,4) -> B034 | E35: 0 | F35: 0 | G35: 0 | H35: 1 | I35: 4 | J35: =P35+Q35+R35+'PresenceAbsence kleine Plots'!C35 -> 3 | K35: 2 | L35: 0 | M35: 1 | N35: 1 | O35: 1 | P35: 0 | Q35: 1 | R35: 1
A36: B1B035 | B36: S04M24 | C36: =LEFT(A36,2) -> B1 | D36: =RIGHT(A36,4) -> B035 | E36: 0 | F36: 0 | G36: 0 | H36: 1 | I36: 4 | J36: 2 | K36: 3 | L36: 0 | M36: 0 | N36: 1 | O36: 1 | P36: 0 | Q36: 0 | R36: 1
A37: B1B036 | B37: S01M43 | C37: =LEFT(A37,2) -> B1 | D37: =RIGHT(A37,4) -> B036 | E37: 1 | F37: 0 | G37: 0 | H37: 0 | I37: 1 | J37: =P37+Q37+R37+'PresenceAbsence kleine Plots'!C37 -> 1 | K37: 0 | L37: 0 | M37: 1 | N37: 0 | O37: 0 | P37: 0 | Q37: 1 | R37: 0
A38: B1B037 | B38: S01M10 | C38: =LEFT(A38,2) -> B1 | D38: =RIGHT(A38,4) -> B037 | E38: 1 | F38: 1 | G38: 0 | H38: 1 | I38: 1 | J38: =P38+Q38+R38+'PresenceAbsence kleine Plots'!C38 -> 1 | K38: 0 | L38: 0 | M38: 1 | N38: 0 | O38: 0 | P38: 0 | Q38: 1 | R38: 0
A39: B1B038 | B39: S01M04 | C39: =LEFT(A39,2) -> B1 | D39: =RIGHT(A39,4) -> B038 | E39: 1 | F39: 1 | G39: 0 | H39: 0 | I39: 1 | J39: 1 | K39: 1 | L39: 0 | M39: 0 | N39: 0 | O39: 1 | P39: 0 | Q39: 0 | R39: 0
A40: B1B039 | B40: S02M40 | C40: =LEFT(A40,2) -> B1 | D40: =RIGHT(A40,4) -> B039 | E40: 0 | F40: 0 | G40: 0 | H40: 1 | I40: 2 | J40: 2 | K40: 1 | L40: 0 | M40: 0 | N40: 1 | O40: 1 | P40: 0 | Q40: 0 | R40: 1
...
